<?xml version="1.0" encoding="UTF-8"?>
<robot xmlns:xacro="http://www.ros.org/wiki/xacro" name="drc_skeleton">
<!--<robot xmlns="http://drake.mit.edu"-->
 <!--xmlns:xsi="http://www.w3.org/2001/XMLSchema-instance"-->
 <!--xsi:schemaLocation="http://drake.mit.edu ../../../doc/drakeURDF.xsd" name="hatlas">-->
  <material name="LightGrey">
      <color rgba="0.8 0.8 0.8 1.0"/>
  </material>
  <material name="Grey">
      <color rgba="0.6 0.6 0.6 1.0"/>
  </material>
  <material name="DarkGrey">
      <color rgba="0.3 0.3 0.3 1.0"/>
  </material>
  <material name="Black">
      <color rgba="0.1 0.1 0.1 1.0"/>
  </material>
  <parameter name="m__pelvis" value="11.0552"/>
  <parameter name="com_x__pelvis" value="0"/>
  <parameter name="com_z__pelvis" value="-0.086"/>
  <link name="pelvis">
      <inertial>
         <origin xyz="$com_x__pelvis 0 $com_z__pelvis"/>
         <mass value="$m__pelvis"/>
         <inertia ixx="0.1950" ixy="0.0" ixz="0.0" iyy="0.1934" iyz="0.0" izz="0.0886"/>
      </inertial>
      <visual>
         <origin rpy="0 0 0" xyz="0 0 -0.0987"/>
         <geometry>
            <cylinder length="0.1575" radius="0.025"/>
         </geometry>
         <material name="LightGrey"/>
      </visual>
  </link>
  <parameter name="m__torso" value="17.307"/>
  <parameter name="com_x__torso" value="0"/>
  <parameter name="com_z__torso" value="0"/>
  <link name="torso">
      <inertial>
         <origin xyz="$com_x__torso 0 $com_z__torso"/>
         <mass value="$m__torso"/>
         <inertia ixx="0.6908" ixy="0.0" ixz="0.0" iyy="0.3763" iyz="0.0" izz="0.4065"/>
      </inertial>
      <visual>
         <origin rpy="0 0 0" xyz="0.0 0.0 0.23927308"/>
         <geometry>
            <cylinder length="0.47854616" radius="0.025"/>
         </geometry>
         <material name="LightGrey"/>
      </visual>
  </link>
  <parameter name="m__uleg" value="6.7704"/>
  <parameter name="com_x__uleg" value="0"/>
  <parameter name="com_z__uleg" value="0"/>
  <link name="uleg">
      <inertial>
         <origin xyz="$com_x__uleg 0 $com_z__uleg"/>
         <mass value="$m__uleg"/>
         <inertia ixx="0.1341" ixy="0.0" ixz="0.0" iyy="0.1341" iyz="0.0" izz="0.0097"/>
      </inertial>
      <visual>
         <origin rpy="0 0 0" xyz="0.0 0.0 -0.23927308"/>
         <geometry>
            <cylinder length="0.43854616" radius="0.025"/>
         </geometry>
         <material name="LightGrey"/>
      </visual>
  </link>
  <parameter name="m__lleg" value="5.0778"/>
  <parameter name="com_x__lleg" value="0"/>
  <parameter name="com_z__lleg" value="0"/>
  <link name="lleg">
      <inertial>
         <origin xyz="$com_x__lleg 0 $com_z__lleg"/>
         <mass value="$m__lleg"/>
         <inertia ixx="0.0839686075882" ixy="0.0" ixz="0.0" iyy="0.0839686075882" iyz="0.0"
                  izz="0.00728566233332"/>
      </inertial>
      <visual>
         <origin rpy="0 0 0" xyz="0 0 -0.21784564"/>
         <geometry>
            <cylinder length="0.39569128" radius="0.025"/>
         </geometry>
         <material name="LightGrey"/>
      </visual>
  </link>
  <link name="foot">
      <inertial>
         <origin xyz="0 0 -0.0226"/>
         <mass value="4"/>
         <inertia ixx="0.0033" ixy="0.0" ixz="0.0" iyy="0.0078" iyz="0.0" izz="0.0063"/>
      </inertial>
      <visual>
         <origin rpy="0 0 0" xyz="0 0 -0.021695283"/>
         <geometry>
            <cylinder length="0.043390566" radius="0.025"/>
         </geometry>
         <material name="LightGrey"/>
      </visual>
      <visual>
         <origin rpy="0 0 0" xyz="0.087138256 0 -0.0377"/>
         <geometry>
            <box size="0.224276512 0.06 0.015"/>
         </geometry>
         <material name="LightGrey"/>
      </visual>
      <collision>
         <origin rpy="0 0 0" xyz="-0.025 0 -0.0452"/>
         <geometry>
            <sphere radius="0"/>
         </geometry>
      </collision>
      <collision>
         <origin rpy="0 0 0" xyz="0.199276512 0 -0.0452"/>
         <geometry>
            <sphere radius="0"/>
         </geometry>
      </collision>
  </link>
  <joint name="BackPitch" type="revolute">
      <parent link="pelvis"/>
      <child link="torso"/>
      <origin rpy="0 0 0" xyz="0 0 0"/>
      <axis xyz="0 1 0"/>
      <limit effort="180" lower="-0." upper="0.43633231275" velocity="3"/>
      <dynamics damping="1" friction="10"/>
  </joint>
  <transmission name="BackPitch_trans" type="SimpleTransmission">
      <actuator name="BackPitchTorque"/>
      <joint name="BackPitch"/>
      <mechanicalReduction>1</mechanicalReduction>
  </transmission>
  <joint name="RHipPitch" type="revolute">
      <parent link="pelvis"/>
      <child link="uleg"/>
      <origin rpy="0 0 0" xyz="0 0 -0.152491948"/>
      <axis xyz="0 1 0"/>
      <limit effort="260" lower="-1.745329251" upper="0.3490658502" velocity="3"/>
      <dynamics damping="1" friction="10"/>
  </joint>
  <transmission name="RHipPitch_trans" type="SimpleTransmission">
      <actuator name="RHipPitchTorque"/>
      <joint name="RHipPitch"/>
      <mechanicalReduction>1</mechanicalReduction>
  </transmission>
  <joint name="RKneePitch" type="revolute">
      <parent link="uleg"/>
      <child link="lleg"/>
      <origin rpy="0 0 0" xyz="0 0 -0.47854616"/>
      <axis xyz="0 1 0"/>
      <limit effort="220" lower="0.0" upper="2.35619448885" velocity="3"/>
      <dynamics damping="1" friction="10"/>
  </joint>
  <transmission name="RKneePitch_trans" type="SimpleTransmission">
      <actuator name="RKneePitchTorque"/>
      <joint name="RKneePitch"/>
      <mechanicalReduction>1</mechanicalReduction>
  </transmission>
  <joint name="RAnklePitch" type="revolute">
      <parent link="lleg"/>
      <child link="foot"/>
      <origin rpy="0 0 0" xyz="0 0 -0.43569128"/>
      <axis xyz="0 1 0"/>
      <limit effort="220" lower="-0.6981317004" upper="0.6981317004" velocity="3"/>
      <dynamics damping="1" friction="10"/>
  </joint>
  <transmission name="RAnklePitch_trans" type="SimpleTransmission">
      <actuator name="RAnklePitchTorque"/>
      <joint name="RAnklePitch"/>
      <mechanicalReduction>1</mechanicalReduction>
  </transmission>
</robot>
